<!doctype html>
<html lang="en">

<head>
    <meta charset="UTF-8">
    <meta name="viewport"
        content="width=device-width, user-scalable=no, initial-scale=1.0, maximum-scale=1.0, minimum-scale=1.0">
    <meta http-equiv="X-UA-Compatible" content="ie=edge">
    <title>7_catch方法-异常穿透</title>
    <script src="Promise.js"></script>
</head>

<body>

    <script>
        /*
          promise异常传透?
            (1)	当使用promise的then链式调用时, 可以在最后指定失败的回调,
            (2)	前面任何操作出了异常, 都会传到最后失败的回调中处理
         */

        /* 封装思路:(catch是谁的方法?)
           1. 直接catch处理(思路:给catch函数第一个参数设置默认值为undefined?为什么)
           2. 链式调用中不传第二个失败的回调,需要在函数调用前对失败的回调做检测
           3. 链式调用catch捕获错误后再继续链式调用会怎么样?
        */
        let p = new Promise((resolve, reject) => {
            // reject('失败啦')
            resolve('ok')
        });

        // 直接处理
        // let result = p.catch(
        //     reason =>{
        //         console.error(reason);
        //     }
        // );

        // console.log(result)
        //异常穿透
        p.then(
            value => {
                // throw '失败啦!!';
            },
            // reason=>{
            //     throw reason
            // }
        )
        .then(
            value => {
                console.log('这个有点难度!!');
                // return '异常穿透';
            },
            // reason=>{
            //     throw reason
            // }
        ).catch(// then(undefined, onRejected);
            reason => {
                console.error(reason);
            }
        )
        .then(
            value => {
                console.log(value);
            }
        )
    </script>

</body>

</html>